{'$type': '$transaction', '$api_key': '6a60d865d2af9bde', '$user_id': 'kleyfrisoli@gmail.com', '$amount': 7800000, '$currency_code': 'USD', '$user_email': 'kleyfrisoli@gmail.com', '$order_id': '1154494', '$transaction_id': '1154494', '$transaction_type': '$sale', '$transaction_status': '$success', '$ip': None, '$time': 1689029204, '$payment_method': {'$payment_type': '$credit_card', '$payment_gateway': '$bluesnap', '$account_holder_name': 'Velasquez Kley', '$card_bin': '516794', '$card_last4': '3565'}, '$merchant_profile': {'$merchant_id': '17', '$merchant_name': 'Ridery'}}
<Response [200]>

{'$type': '$transaction', '$api_key': '6a60d865d2af9bde', '$user_id': 'elianajf59@gmail.com', '$amount': 1990000, '$currency_code': 'USD', '$user_email': 'elianajf59@gmail.com', '$order_id': '1154497', '$transaction_id': '1154497', '$transaction_type': '$sale', '$transaction_status': '$success', '$ip': None, '$time': 1689029328, '$payment_method': {'$payment_type': '$credit_card', '$payment_gateway': '$bluesnap', '$account_holder_name': 'Eliana C', '$card_bin': '510256', '$card_last4': '1794'}, '$merchant_profile': {'$merchant_id': '17', '$merchant_name': 'Ridery'}}
<Response [200]>

{'$type': '$transaction', '$api_key': '6a60d865d2af9bde', '$user_id': 'farialat@hotmail.com', '$amount': 10790000, '$currency_code': 'USD', '$user_email': 'farialat@hotmail.com', '$decline_category': '$other', '$order_id': '1154499', '$transaction_id': '1154499', '$transaction_type': '$sale', '$transaction_status': '$failure', '$ip': None, '$time': 1689029346, '$payment_method': {'$payment_type': '$credit_card', '$payment_gateway': '$bluesnap', '$account_holder_name': 'faridash casanova', '$card_last4': '9439'}, '$merchant_profile': {'$merchant_id': '17', '$merchant_name': 'Ridery'}}
Traceback (most recent call last):
  File "C:\Users\daldana_lukapay\AppData\Local\Programs\Python\Python312\Lib\site-packages\urllib3\connectionpool.py", line 790, in urlopen
    response = self._make_request(
               ^^^^^^^^^^^^^^^^^^^
  File "C:\Users\daldana_lukapay\AppData\Local\Programs\Python\Python312\Lib\site-packages\urllib3\connectionpool.py", line 536, in _make_request
    response = conn.getresponse()
               ^^^^^^^^^^^^^^^^^^
  File "C:\Users\daldana_lukapay\AppData\Local\Programs\Python\Python312\Lib\site-packages\urllib3\connection.py", line 461, in getresponse
    httplib_response = super().getresponse()
                       ^^^^^^^^^^^^^^^^^^^^^
  File "C:\Users\daldana_lukapay\AppData\Local\Programs\Python\Python312\Lib\http\client.py", line 1411, in getresponse
    response.begin()
  File "C:\Users\daldana_lukapay\AppData\Local\Programs\Python\Python312\Lib\http\client.py", line 324, in begin
    version, status, reason = self._read_status()
                              ^^^^^^^^^^^^^^^^^^^
  File "C:\Users\daldana_lukapay\AppData\Local\Programs\Python\Python312\Lib\http\client.py", line 293, in _read_status
    raise RemoteDisconnected("Remote end closed connection without"
http.client.RemoteDisconnected: Remote end closed connection without response

During handling of the above exception, another exception occurred:

Traceback (most recent call last):
  File "C:\Users\daldana_lukapay\AppData\Local\Programs\Python\Python312\Lib\site-packages\requests\adapters.py", line 486, in send
    resp = conn.urlopen(
           ^^^^^^^^^^^^^
  File "C:\Users\daldana_lukapay\AppData\Local\Programs\Python\Python312\Lib\site-packages\urllib3\connectionpool.py", line 844, in urlopen
    retries = retries.increment(
              ^^^^^^^^^^^^^^^^^^
  File "C:\Users\daldana_lukapay\AppData\Local\Programs\Python\Python312\Lib\site-packages\urllib3\util\retry.py", line 470, in increment
    raise reraise(type(error), error, _stacktrace)
          ^^^^^^^^^^^^^^^^^^^^^^^^^^^^^^^^^^^^^^^^
  File "C:\Users\daldana_lukapay\AppData\Local\Programs\Python\Python312\Lib\site-packages\urllib3\util\util.py", line 38, in reraise
    raise value.with_traceback(tb)
  File "C:\Users\daldana_lukapay\AppData\Local\Programs\Python\Python312\Lib\site-packages\urllib3\connectionpool.py", line 790, in urlopen
    response = self._make_request(
               ^^^^^^^^^^^^^^^^^^^
  File "C:\Users\daldana_lukapay\AppData\Local\Programs\Python\Python312\Lib\site-packages\urllib3\connectionpool.py", line 536, in _make_request
    response = conn.getresponse()
               ^^^^^^^^^^^^^^^^^^
  File "C:\Users\daldana_lukapay\AppData\Local\Programs\Python\Python312\Lib\site-packages\urllib3\connection.py", line 461, in getresponse
    httplib_response = super().getresponse()
                       ^^^^^^^^^^^^^^^^^^^^^
  File "C:\Users\daldana_lukapay\AppData\Local\Programs\Python\Python312\Lib\http\client.py", line 1411, in getresponse
    response.begin()
  File "C:\Users\daldana_lukapay\AppData\Local\Programs\Python\Python312\Lib\http\client.py", line 324, in begin
    version, status, reason = self._read_status()
                              ^^^^^^^^^^^^^^^^^^^
  File "C:\Users\daldana_lukapay\AppData\Local\Programs\Python\Python312\Lib\http\client.py", line 293, in _read_status
    raise RemoteDisconnected("Remote end closed connection without"
urllib3.exceptions.ProtocolError: ('Connection aborted.', RemoteDisconnected('Remote end closed connection without response'))

During handling of the above exception, another exception occurred:

Traceback (most recent call last):
  File "c:\Users\daldana_lukapay\Documents\Luka\data_sending.py", line 450, in <module>
    main()
  File "c:\Users\daldana_lukapay\Documents\Luka\data_sending.py", line 445, in main
    json_creation_transaction(rows)
  File "c:\Users\daldana_lukapay\Documents\Luka\data_sending.py", line 84, in json_creation_transaction
    send(data = properties)
  File "c:\Users\daldana_lukapay\Documents\Luka\data_sending.py", line 9, in send
    response = requests.post(api_url, json=data)
               ^^^^^^^^^^^^^^^^^^^^^^^^^^^^^^^^^
  File "C:\Users\daldana_lukapay\AppData\Local\Programs\Python\Python312\Lib\site-packages\requests\api.py", line 115, in post
    return request("post", url, data=data, json=json, **kwargs)
           ^^^^^^^^^^^^^^^^^^^^^^^^^^^^^^^^^^^^^^^^^^^^^^^^^^^^
  File "C:\Users\daldana_lukapay\AppData\Local\Programs\Python\Python312\Lib\site-packages\requests\api.py", line 59, in request
    return session.request(method=method, url=url, **kwargs)
           ^^^^^^^^^^^^^^^^^^^^^^^^^^^^^^^^^^^^^^^^^^^^^^^^^
  File "C:\Users\daldana_lukapay\AppData\Local\Programs\Python\Python312\Lib\site-packages\requests\sessions.py", line 589, in request
    resp = self.send(prep, **send_kwargs)
           ^^^^^^^^^^^^^^^^^^^^^^^^^^^^^^
  File "C:\Users\daldana_lukapay\AppData\Local\Programs\Python\Python312\Lib\site-packages\requests\sessions.py", line 703, in send
    r = adapter.send(request, **kwargs)
        ^^^^^^^^^^^^^^^^^^^^^^^^^^^^^^^
  File "C:\Users\daldana_lukapay\AppData\Local\Programs\Python\Python312\Lib\site-packages\requests\adapters.py", line 501, in send
    raise ConnectionError(err, request=request)
requests.exceptions.ConnectionError: ('Connection aborted.', RemoteDisconnected('Remote end closed connection without response'))